<?xml version="1.0"?>
<robot name="my_robot" xmlns:xacro="http://ros.org/wiki/xacro">

<!--part.xacro-->
<xacro:include filename="/home/selawe/my_robot_ws/src/robot_description/urdf/part.xacro"/>
  
  <!-- Base -->
  <link name="base_footprint"/>

  <link name="base_link">
    
    <visual>
      <geometry>
        <box size="${length_box} ${width_box} ${hight_box}"/>
      </geometry>
      <origin xyz="0 0 0.1" rpy="0 0 0"/>
      <material name="green"/>
    </visual>
    
    <collision>
      <geometry>
        <box size="${length_box} ${width_box} ${hight_box}"/>
      </geometry>
      <origin xyz="0 0 0.1" rpy="0 0 0"/>
    </collision>
    
    <inertial>
      <mass value="${mass}"/>
      <inertia ixx="${(mass/12.0) * (hight_box*hight_box + length_box*length_box)}" ixy="0.0" ixz="0.0"
               iyy="${(mass/12.0) * (width_box*width_box + length_box*length_box)}" iyz="0.0"
               izz="${(mass/12.0) * (width_box*width_box + hight_box*hight_box)}" /> 
    </inertial>

  </link>




  <!--Links (Components)-->
  
  <!--CYLINDER-->
  <xacro:cylinder_link name="lidar" radius="${lidar_radius}" length="${lidar_length}" mass="${mass}" color="gray" xyz="0 0 0" rpy="0 0 0"/>
  <xacro:cylinder_link name="right_wheel" radius="${wheel_radius}" length="${wheel_length}" mass="${mass}" color="gray" xyz="0 0 0" rpy="1.57 0 0"/>
  <xacro:cylinder_link name="left_wheel" radius="${wheel_radius}" length="${wheel_length}" mass="${mass}" color="gray" xyz="0 0 0" rpy="1.57 0 0"/>
  <xacro:cylinder_link name="arm" radius="${arm_radius}" length="${arm_length}" mass="${mass}" color="black" xyz="0 0 0" rpy="0 1.57 0"/>
  
  <!--CASTER-->
  <link name="caster_wheel">
    
    <visual>
      <geometry>
        <sphere radius="${caster_radius}"/>
      </geometry>
      <origin xyz="0 0 0" rpy="0 0 0"/>
      <material name="gray"/>
    </visual>

    <collision>
      <geometry>
        <sphere radius="${caster_radius}"/>
      </geometry>
    </collision>

    <inertial>
      <mass value="${mass}"/>
      <inertia ixx="${(2/5) * mass * caster_radius * caster_radius}" ixy="0.0" ixz="0.0"
                     iyy="${(2/5) * mass * caster_radius * caster_radius}" iyz="0.0"
                     izz="${(2/5) * mass * caster_radius * caster_radius}" />
    </inertial>

  </link>

  <!--GRIPPER-->
  <xacro:mesh_link name="right_gripper" mesh_path="package://urdf_tutorial/meshes/l_finger_tip.dae" scale="${gripper_scale}" xyz="0 0 0" rpy="0 0 0.1"/>
  <xacro:mesh_link name="left_gripper"  mesh_path="package://urdf_tutorial/meshes/l_finger_tip.dae" scale="${gripper_scale}" xyz="0 0 0" rpy="3.1415 0 -0.1"/>



  
  
  <!-- Joints -->
  <joint name="footprint_to_base" type="fixed">
    <parent link="base_footprint"/>
    <child link="base_link"/>
    <origin xyz="0 0 0.1" rpy="0 0 0"/>
  </joint>

  <joint name="base_to_lidar" type="fixed">
    <parent link="base_link"/>
    <child link="lidar"/>
    <origin xyz="0 0 0.225" rpy="0 0 0"/>
  </joint>

  <joint name="base_to_left_wheel" type="continuous">
    <parent link="base_link"/>
    <child link="left_wheel"/>
    <origin xyz="-0.15 0.225 0" rpy="0 0 0"/>
    <axis xyz="0 1 0"/>
  </joint>

  <joint name="base_to_right_wheel" type="continuous">
    <parent link="base_link"/>
    <child link="right_wheel"/>
    <origin xyz="-0.15 -0.225 0" rpy="0 0 0"/>
    <axis xyz="0 1 0"/>
  </joint>

  <joint name="base_to_caster" type="fixed">
    <parent link="base_link"/>
    <child link="caster_wheel"/>
    <origin xyz="0.15 0 -0.05" rpy="0 0 0"/>
  </joint>

  <joint name="base_to_arm" type="fixed">
    <parent link="base_link"/>
    <child link="arm"/>
    <origin xyz="0.35 0 0.1" rpy="0 0 0"/>
  </joint>

  <joint name="right_gripper_joint" type="revolute">
    <parent link="base_link"/>
    <child link="right_gripper"/>
    <origin xyz="0.43 0.025 0.1" rpy="0 0 0"/>
    <axis xyz="0 0 1"/>
    <limit effort="1000.0" lower="0.0" upper="0.548" velocity="0.5"/>
  </joint>

  <joint name="left_gripper_joint" type="revolute">
    <parent link="base_link"/>
    <child link="left_gripper"/>
    <origin xyz="0.43 -0.025 0.1" rpy="0 0 0"/>
    <axis xyz="0 0 1"/>
    <limit effort="1000.0" lower="-0.548" upper="0.0" velocity="0.5"/>
  </joint>







  <!--caster wheel-->
  <gazebo reference="caster_wheel">
    <mu1 value="0.1"/>
    <mu2 value="0.1"/>
  </gazebo>

  <!--diff wheel-->
  <gazebo>
    <plugin name="diff_drive_controller" filename="libgazebo_ros_diff_drive.so">
      <ros>
        <namespace>/</namespace>
        <remapping>cmd_vel:=cmd_vel</remapping> <!-- ROS 2 topic -->
      </ros>
      <left_joint>base_to_left_wheel</left_joint>
      <right_joint>base_to_right_wheel</right_joint>
      <wheel_separation>0.45</wheel_separation>
      <wheel_radius>0.1</wheel_radius>
      <publish_odom>true</publish_odom>
      <odom_topic>odom</odom_topic>
      <robot_base_frame>base_footprint</robot_base_frame>
    </plugin>
  </gazebo>

  <!--joint_state_pub-->
  <gazebo>
    <plugin name="joint_state_publisher" filename="libgazebo_ros_joint_state_publisher.so">
      <ros>
        <namespace>/</namespace>
      </ros>
      <publish_rate>50</publish_rate>
    </plugin>
  </gazebo>


</robot>